<?xml version="1.0" encoding="UTF-8"?>
<sdf version='1.9'>
  <model name='uav_base'>
    <pose>0 0 0.12 0 0 0</pose>
    <self_collide>false</self_collide>
    <static>false</static>
    <link name="base_link">
      <inertial>
        <mass>0.25</mass>
        <inertia>
          <ixx>0.000677083333</ixx>
          <ixy>0</ixy>
          <ixz>0</ixz>
          <iyy>0.000677083333</iyy>
          <iyz>0</iyz>
          <izz>0.00125</izz>
        </inertia>
      </inertial>
      <gravity>true</gravity>
      <velocity_decay/>
      <visual name="base_link_visual">
        <pose>0 0 0.0125 0 0 3.141592654</pose>
        <geometry>
          <mesh>
            <scale>0.5 0.5 0.5</scale>
            <uri>model://uav_base/meshes/NXP-HGD-CF.dae</uri>
          </mesh>
        </geometry>
      </visual>
      <visual name="5010_motor_base_0">
        <pose>0.09 0.09 0.016 0 0 -0.45</pose>
        <geometry>
          <mesh>
            <scale>0.5 0.5 0.5</scale>
            <uri>model://uav_base/meshes/5010Base.dae</uri>
          </mesh>
        </geometry>
      </visual>
      <visual name="5010_motor_base_1">
        <pose>-0.09 0.09 0.016 0 0 -0.45</pose>
        <geometry>
          <mesh>
            <scale>0.5 0.5 0.5</scale>
            <uri>model://uav_base/meshes/5010Base.dae</uri>
          </mesh>
        </geometry>
      </visual>
      <visual name="5010_motor_base_2">
        <pose>0.09 -0.09 0.016 0 0 -0.45</pose>
        <geometry>
          <mesh>
            <scale>0.5 0.5 0.5</scale>
            <uri>model://uav_base/meshes/5010Base.dae</uri>
          </mesh>
        </geometry>
      </visual>
      <visual name="5010_motor_base_3">
        <pose>-0.09 -0.09 0.016 0 0 -0.45</pose>
        <geometry>
          <mesh>
            <scale>0.5 0.5 0.5</scale>
            <uri>model://uav_base/meshes/5010Base.dae</uri>
          </mesh>
        </geometry>
      </visual>
      <visual name="NXP_FMUK66_FRONT">
        <pose>0.0235 0.0005 0.0215 1 0 1.57</pose>
        <cast_shadows>false</cast_shadows>
        <geometry>
          <plane>
            <normal>0 0 1</normal>
            <size>0.0065 0.0035</size>
          </plane>
        </geometry>
        <material>
          <diffuse>1.0 1.0 1.0</diffuse>
          <specular>1.0 1.0 1.0</specular>
          <pbr>
            <metal>
              <albedo_map>model://uav_base/materials/textures/nxp.png</albedo_map>
            </metal>
          </pbr>
        </material>
      </visual>
      <visual name="NXP_FMUK66_TOP">
        <pose>-0.0115 0 0.02575 0 0 -1.57</pose>
        <cast_shadows>false</cast_shadows>
        <geometry>
          <plane>
            <normal>0 0 1</normal>
            <size>0.0065 0.0035</size>
          </plane>
        </geometry>
        <material>
          <diffuse>1.0 1.0 1.0</diffuse>
          <specular>1.0 1.0 1.0</specular>
          <pbr>
            <metal>
              <albedo_map>model://uav_base/materials/textures/nxp.png</albedo_map>
            </metal>
          </pbr>
        </material>
      </visual>
      <visual name="RDDRONE_FMUK66_TOP">
        <pose>-0.015 0 0.02575 0 0 -1.57</pose>
        <cast_shadows>false</cast_shadows>
        <geometry>
          <plane>
            <normal>0 0 1</normal>
            <size>0.016 0.0017</size>
          </plane>
        </geometry>
        <material>
          <diffuse>1.0 1.0 1.0</diffuse>
          <specular>1.0 1.0 1.0</specular>
          <pbr>
            <metal>
              <albedo_map>model://uav_base/materials/textures/rd.png</albedo_map>
            </metal>
          </pbr>
        </material>
      </visual>
      <collision name="base_link_collision_0">
        <pose>0 0 0.0035 0 0 0</pose>
        <geometry>
          <box>
            <size>0.176776695297 0.176776695297 0.025</size>
          </box>
        </geometry>
        <surface>
          <contact>
            <ode>
              <min_depth>0.001</min_depth>
              <max_vel>0</max_vel>
            </ode>
          </contact>
          <friction>
            <ode/>
          </friction>
        </surface>
      </collision>
      <collision name="base_link_collision_1">
        <pose>0 -0.049 -0.0615 -0.35 0 0</pose>
        <geometry>
          <box>
            <size>0.0075 0.0075 0.105</size>
          </box>
        </geometry>
        <surface>
          <contact>
            <ode>
              <min_depth>0.001</min_depth>
              <max_vel>0</max_vel>
            </ode>
          </contact>
          <friction>
            <ode/>
          </friction>
        </surface>
      </collision>
      <collision name="base_link_collision_2">
        <pose>0 0.049 -0.0615 0.35 0 0</pose>
        <geometry>
          <box>
            <size>0.0075 0.0075 0.105</size>
          </box>
        </geometry>
        <surface>
          <contact>
            <ode>
              <min_depth>0.001</min_depth>
              <max_vel>0</max_vel>
            </ode>
          </contact>
          <friction>
            <ode/>
          </friction>
        </surface>
      </collision>
      <collision name="base_link_collision_3">
        <pose>0 -0.066 -0.10975 0 0 0</pose>
        <geometry>
          <box>
            <size>0.125 0.0075 0.0075</size>
          </box>
        </geometry>
        <surface>
          <contact>
            <ode>
              <min_depth>0.001</min_depth>
              <max_vel>0</max_vel>
            </ode>
          </contact>
          <friction>
            <ode/>
          </friction>
        </surface>
      </collision>
      <collision name="base_link_collision_4">
        <pose>0 0.066 -0.10975 0 0 0</pose>
        <geometry>
          <box>
            <size>0.125 0.0075 0.0075</size>
          </box>
        </geometry>
        <surface>
          <contact>
            <ode>
              <min_depth>0.001</min_depth>
              <max_vel>0</max_vel>
            </ode>
          </contact>
          <friction>
            <ode/>
          </friction>
        </surface>
      </collision>
      <sensor name="air_pressure_sensor" type="air_pressure">
        <always_on>1</always_on>
        <update_rate>50</update_rate>
        <air_pressure>
          <pressure>
            <noise type="gaussian">
              <mean>0</mean>
              <stddev>0.01</stddev>
            </noise>
          </pressure>
        </air_pressure>
      </sensor>
      <sensor name="imu_sensor" type="imu">
        <always_on>1</always_on>
        <update_rate>250</update_rate>
        <imu>
          <angular_velocity>
            <x>
              <noise type="gaussian">
                <mean>0</mean>
                <stddev>0.00018665</stddev>
                <dynamic_bias_stddev>3.8785e-05</dynamic_bias_stddev>
                <dynamic_bias_correlation_time>1000</dynamic_bias_correlation_time>
              </noise>
            </x>
            <y>
              <noise type="gaussian">
                <mean>0</mean>
                <stddev>0.00018665</stddev>
                <dynamic_bias_stddev>3.8785e-05</dynamic_bias_stddev>
                <dynamic_bias_correlation_time>1000</dynamic_bias_correlation_time>
              </noise>
            </y>
            <z>
              <noise type="gaussian">
                <mean>0</mean>
                <stddev>0.00018665</stddev>
                <dynamic_bias_stddev>3.8785e-05</dynamic_bias_stddev>
                <dynamic_bias_correlation_time>1000</dynamic_bias_correlation_time>
              </noise>
            </z>
          </angular_velocity>
          <linear_acceleration>
            <x>
              <noise type="gaussian">
                <mean>0</mean>
                <stddev>0.00186</stddev>
                <dynamic_bias_stddev>0.006</dynamic_bias_stddev>
                <dynamic_bias_correlation_time>300</dynamic_bias_correlation_time>
              </noise>
            </x>
            <y>
              <noise type="gaussian">
                <mean>0</mean>
                <stddev>0.00186</stddev>
                <dynamic_bias_stddev>0.006</dynamic_bias_stddev>
                <dynamic_bias_correlation_time>300</dynamic_bias_correlation_time>
              </noise>
            </y>
            <z>
              <noise type="gaussian">
                <mean>0</mean>
                <stddev>0.00186</stddev>
                <dynamic_bias_stddev>0.006</dynamic_bias_stddev>
                <dynamic_bias_correlation_time>300</dynamic_bias_correlation_time>
              </noise>
            </z>
          </linear_acceleration>
        </imu>
      </sensor>
      <sensor name="navsat_sensor" type="navsat">
        <always_on>1</always_on>
        <update_rate>30</update_rate>
      </sensor>
      <visual name="mono_camera_visual">
        <pose>0.05 0 -0.02 0 1.570796327 0</pose>
        <geometry>
          <box>
            <size>0.022 0.018 0.014</size>
          </box>
        </geometry>
        <material>
          <ambient>0.05 0.05 0.05 1</ambient>
          <diffuse>0.08 0.08 0.08 1</diffuse>
          <specular>0.2 0.2 0.2 1</specular>
        </material>
      </visual>
      <sensor name="mono_camera" type="camera">
        <always_on>1</always_on>
        <update_rate>60</update_rate>
        <pose>0.05 0 -0.02 0 1.570796327 0</pose>
        <camera>
          <horizontal_fov>1.3962634</horizontal_fov>
          <image>
            <width>1280</width>
            <height>720</height>
            <format>R8G8B8</format>
          </image>
          <clip>
            <near>0.05</near>
            <far>100</far>
          </clip>
        </camera>
        <visualize>false</visualize>
      </sensor>
      <visual name="stereo_depth_camera_visual">
        <pose>0.05 0 0.045 0 0 0</pose>
        <geometry>
          <box>
            <size>0.0307 0.09 0.025</size>
          </box>
        </geometry>
        <material>
          <ambient>0.05 0.05 0.05 1</ambient>
          <diffuse>0.08 0.08 0.08 1</diffuse>
          <specular>0.2 0.2 0.2 1</specular>
        </material>
      </visual>
      <sensor name="stereo_depth_camera_rgb" type="camera">
        <always_on>1</always_on>
        <update_rate>30</update_rate>
        <pose>0.05 0 0.045 0 0 0</pose>
        <camera>
          <horizontal_fov>1.500983157</horizontal_fov>
          <image>
            <width>1920</width>
            <height>1080</height>
            <format>R8G8B8</format>
          </image>
          <clip>
            <near>0.10</near>
            <far>20.0</far>
          </clip>
        </camera>
        <visualize>false</visualize>
      </sensor>
      <sensor name="stereo_depth_camera_depth" type="depth_camera">
        <always_on>1</always_on>
        <update_rate>30</update_rate>
        <pose>0.05 0 0.045 0 0 0</pose>
        <camera>
          <horizontal_fov>1.570796327</horizontal_fov>
          <image>
            <width>1280</width>
            <height>800</height>
            <format>R_FLOAT32</format>
          </image>
          <clip>
            <near>0.10</near>
            <far>20.0</far>
          </clip>
        </camera>
        <visualize>false</visualize>
      </sensor>
    </link>
    <link name="rotor_0">
      <gravity>true</gravity>
      <self_collide>false</self_collide>
      <velocity_decay/>
      <pose>0.09 -0.09 0.03 0 0 0</pose>
      <inertial>
          <mass>0.002009615385</mass>
          <inertia>
            <ixx>0.00000001202</ixx>
            <iyy>0.00000081612</iyy>
            <izz>0.000000828081</izz>
          </inertia>
        </inertial>
      <visual name="rotor_0_visual">
        <pose>-0.011 -0.073192307692 -0.008 0 0 0</pose>
        <geometry>
          <mesh>
            <scale>0.423076923077 0.423076923077 0.423076923077</scale>
            <uri>model://uav_base/meshes/1345_prop_cw.stl</uri>
          </mesh>
        </geometry>
        <material>
          <script>
            <name>Gazebo/DarkGrey</name>
            <uri>file://media/materials/scripts/gazebo.material</uri>
          </script>
        </material>
      </visual>
      <visual name="rotor_0_visual_motor_bell">
        <pose>0 0 -0.016 0 0 0</pose>
        <geometry>
          <mesh>
            <scale>0.5 0.5 0.5</scale>
            <uri>model://uav_base/meshes/5010Bell.dae</uri>
          </mesh>
        </geometry>
      </visual>
      <collision name="rotor_0_collision">
        <pose>0 0 0 0 0 0</pose>
        <geometry>
          <box>
            <size>0.139615384615 0.008461538462 0.000423076923</size>
          </box>
        </geometry>
        <surface>
          <contact>
            <ode>
              <min_depth>0.001</min_depth>
              <max_vel>0</max_vel>
            </ode>
          </contact>
          <friction>
            <ode/>
          </friction>
        </surface>
      </collision>
    </link>
    <joint name="rotor_0_joint" type="revolute">
      <parent>base_link</parent>
      <child>rotor_0</child>
      <axis>
        <xyz>0 0 1</xyz>
        <limit>
          <lower>-1e+16</lower>
          <upper>1e+16</upper>
        </limit>
        <dynamics>
          <spring_reference>0</spring_reference>
          <spring_stiffness>0</spring_stiffness>
        </dynamics>
      </axis>
    </joint>
    <link name="rotor_1">
      <gravity>true</gravity>
      <self_collide>false</self_collide>
      <velocity_decay/>
      <pose>-0.09 0.09 0.03 0 0 0</pose>
      <inertial>
          <mass>0.002009615385</mass>
          <inertia>
            <ixx>0.00000001202</ixx>
            <iyy>0.00000081612</iyy>
            <izz>0.000000828081</izz>
          </inertia>
        </inertial>
      <visual name="rotor_1_visual">
        <pose>-0.011 -0.073192307692 -0.008 0 0 0</pose>
        <geometry>
          <mesh>
            <scale>0.423076923077 0.423076923077 0.423076923077</scale>
            <uri>model://uav_base/meshes/1345_prop_cw.stl</uri>
          </mesh>
        </geometry>
        <material>
          <script>
            <name>Gazebo/DarkGrey</name>
            <uri>file://media/materials/scripts/gazebo.material</uri>
          </script>
        </material>
      </visual>
      <visual name="rotor_1_visual_motor_top">
        <pose>0 0 -0.016 0 0 0</pose>
        <geometry>
          <mesh>
            <scale>0.5 0.5 0.5</scale>
            <uri>model://uav_base/meshes/5010Bell.dae</uri>
          </mesh>
        </geometry>
      </visual>
      <collision name="rotor_1_collision">
        <pose>0 0 0 0 0 0</pose>
        <geometry>
          <box>
            <size>0.139615384615 0.008461538462 0.000423076923</size>
          </box>
        </geometry>
        <surface>
          <contact>
            <ode>
              <min_depth>0.001</min_depth>
              <max_vel>0</max_vel>
            </ode>
          </contact>
          <friction>
            <ode/>
          </friction>
        </surface>
      </collision>
    </link>
    <joint name="rotor_1_joint" type="revolute">
      <parent>base_link</parent>
      <child>rotor_1</child>
      <axis>
        <xyz>0 0 1</xyz>
        <limit>
          <lower>-1e+16</lower>
          <upper>1e+16</upper>
        </limit>
        <dynamics>
          <spring_reference>0</spring_reference>
          <spring_stiffness>0</spring_stiffness>
        </dynamics>
      </axis>
    </joint>
    <link name="rotor_2">
      <gravity>true</gravity>
      <self_collide>false</self_collide>
      <velocity_decay/>
      <pose>0.09 0.09 0.03 0 0 0</pose>
      <inertial>
          <mass>0.002009615385</mass>
          <inertia>
            <ixx>0.00000001202</ixx>
            <iyy>0.00000081612</iyy>
            <izz>0.000000828081</izz>
          </inertia>
        </inertial>
      <visual name="rotor_2_visual">
        <pose>-0.011 -0.073192307692 -0.008 0 0 0</pose>
        <geometry>
          <mesh>
            <scale>0.423076923077 0.423076923077 0.423076923077</scale>
            <uri>model://uav_base/meshes/1345_prop_ccw.stl</uri>
          </mesh>
        </geometry>
        <material>
          <script>
            <name>Gazebo/DarkGrey</name>
            <uri>file://media/materials/scripts/gazebo.material</uri>
          </script>
        </material>
      </visual>
      <visual name="rotor_2_visual_motor_top">
        <pose>0 0 -0.016 0 0 0</pose>
        <geometry>
          <mesh>
            <scale>0.5 0.5 0.5</scale>
            <uri>model://uav_base/meshes/5010Bell.dae</uri>
          </mesh>
        </geometry>
      </visual>
      <collision name="rotor_2_collision">
        <pose>0 0 0 0 0 0</pose>
        <geometry>
          <box>
            <size>0.139615384615 0.008461538462 0.000423076923</size>
          </box>
        </geometry>
        <surface>
          <contact>
            <ode>
              <min_depth>0.001</min_depth>
              <max_vel>0</max_vel>
            </ode>
          </contact>
          <friction>
            <ode/>
          </friction>
        </surface>
      </collision>
    </link>
    <joint name="rotor_2_joint" type="revolute">
      <parent>base_link</parent>
      <child>rotor_2</child>
      <axis>
        <xyz>0 0 1</xyz>
        <limit>
          <lower>-1e+16</lower>
          <upper>1e+16</upper>
        </limit>
        <dynamics>
          <spring_reference>0</spring_reference>
          <spring_stiffness>0</spring_stiffness>
        </dynamics>
      </axis>
    </joint>
    <link name="rotor_3">
      <gravity>true</gravity>
      <self_collide>false</self_collide>
      <velocity_decay/>
      <pose>-0.09 -0.09 0.03 0 0 0</pose>
      <inertial>
          <mass>0.002009615385</mass>
          <inertia>
            <ixx>0.00000001202</ixx>
            <iyy>0.00000081612</iyy>
            <izz>0.000000828081</izz>
          </inertia>
        </inertial>
      <visual name="rotor_3_visual">
        <pose>-0.011 -0.073192307692 -0.008 0 0 0</pose>
        <geometry>
          <mesh>
            <scale>0.423076923077 0.423076923077 0.423076923077</scale>
            <uri>model://uav_base/meshes/1345_prop_ccw.stl</uri>
          </mesh>
        </geometry>
        <material>
          <script>
            <name>Gazebo/DarkGrey</name>
            <uri>file://media/materials/scripts/gazebo.material</uri>
          </script>
        </material>
      </visual>
      <visual name="rotor_3_visual_motor_top">
        <pose>0 0 -0.016 0 0 0</pose>
        <geometry>
          <mesh>
            <scale>0.5 0.5 0.5</scale>
            <uri>model://uav_base/meshes/5010Bell.dae</uri>
          </mesh>
        </geometry>
      </visual>
      <collision name="rotor_3_collision">
        <pose>0 0 0 0 0 0</pose>
        <geometry>
          <box>
            <size>0.139615384615 0.008461538462 0.000423076923</size>
          </box>
        </geometry>
        <surface>
          <contact>
            <ode>
              <min_depth>0.001</min_depth>
              <max_vel>0</max_vel>
            </ode>
          </contact>
          <friction>
            <ode/>
          </friction>
        </surface>
      </collision>
    </link>
    <joint name="rotor_3_joint" type="revolute">
      <parent>base_link</parent>
      <child>rotor_3</child>
      <axis>
        <xyz>0 0 1</xyz>
        <limit>
          <lower>-1e+16</lower>
          <upper>1e+16</upper>
        </limit>
        <dynamics>
          <spring_reference>0</spring_reference>
          <spring_stiffness>0</spring_stiffness>
        </dynamics>
      </axis>
    </joint>
  </model>
</sdf>
