<?xml version="1.0" encoding="UTF-8"?>
<sdf version='1.9'>
  <model name='uav_base'>
    <pose>0 0 0.12 0 0 0</pose>
    <self_collide>false</self_collide>
    <static>false</static>
    <link name="uav_base_link">
      <inertial>
        <mass>1.19196153846</mass>
        <inertia>
          <ixx>0.002926086497</ixx>
          <ixy>0</ixy>
          <ixz>0</ixz>
          <iyy>0.002922870097</iyy>
          <iyz>0</iyz>
          <izz>0.004866464599</izz>
        </inertia>
      </inertial>
      <gravity>true</gravity>
      <velocity_decay/>
      <visual name="uav_base_link_visual">
        <pose>0 0 0 0 0 0</pose>
        <geometry>
          <mesh>
            <scale>1 1 1</scale>
            <uri>model://uav_base/meshes/dj250_airframe.dae</uri>
          </mesh>
        </geometry>
      </visual>
      <!-- Motor base layout follows the configured rotor positions, converted from FRD to FLU by flipping Y.
           Rotor numbering is preserved here: 0=front-right, 1=rear-left, 2=front-left, 3=rear-right. -->
      <visual name="motor_2306_base_0">
        <pose>0.09 -0.09 0.0325 0 0 -0.45</pose>
        <geometry>
          <mesh>
            <scale>1 1 1</scale>
            <uri>model://uav_base/meshes/motor_2306_base.dae</uri>
          </mesh>
        </geometry>
      </visual>
      <visual name="motor_2306_base_1">
        <pose>-0.09 0.09 0.0325 0 0 -0.45</pose>
        <geometry>
          <mesh>
            <scale>1 1 1</scale>
            <uri>model://uav_base/meshes/motor_2306_base.dae</uri>
          </mesh>
        </geometry>
      </visual>
      <visual name="motor_2306_base_2">
        <pose>0.09 0.09 0.0325 0 0 -0.45</pose>
        <geometry>
          <mesh>
            <scale>1 1 1</scale>
            <uri>model://uav_base/meshes/motor_2306_base.dae</uri>
          </mesh>
        </geometry>
      </visual>
      <visual name="motor_2306_base_3">
        <pose>-0.09 -0.09 0.0325 0 0 -0.45</pose>
        <geometry>
          <mesh>
            <scale>1 1 1</scale>
            <uri>model://uav_base/meshes/motor_2306_base.dae</uri>
          </mesh>
        </geometry>
      </visual>
      <visual name="flight_controller_front_marker">
        <pose>0.0235 0.0005 0.0215 1 0 1.57</pose>
        <cast_shadows>false</cast_shadows>
        <geometry>
          <plane>
            <normal>0 0 1</normal>
            <size>0.0065 0.0035</size>
          </plane>
        </geometry>
        <material>
          <ambient>0.85 0.85 0.85 1</ambient>
          <diffuse>0.95 0.95 0.95 1</diffuse>
          <specular>0.2 0.2 0.2 1</specular>
        </material>
      </visual>
      <visual name="flight_controller_top_marker">
        <pose>-0.0115 0 0.02575 0 0 -1.57</pose>
        <cast_shadows>false</cast_shadows>
        <geometry>
          <plane>
            <normal>0 0 1</normal>
            <size>0.0065 0.0035</size>
          </plane>
        </geometry>
        <material>
          <ambient>0.85 0.85 0.85 1</ambient>
          <diffuse>0.95 0.95 0.95 1</diffuse>
          <specular>0.2 0.2 0.2 1</specular>
        </material>
      </visual>
      <visual name="vehicle_top_marker">
        <pose>-0.015 0 0.02575 0 0 -1.57</pose>
        <cast_shadows>false</cast_shadows>
        <geometry>
          <plane>
            <normal>0 0 1</normal>
            <size>0.016 0.0017</size>
          </plane>
        </geometry>
        <material>
          <ambient>0.85 0.85 0.85 1</ambient>
          <diffuse>0.95 0.95 0.95 1</diffuse>
          <specular>0.2 0.2 0.2 1</specular>
        </material>
      </visual>
      <collision name="uav_base_link_collision_body_lower">
        <pose>0.00123 0.00075 0.01450 0 0 0</pose>
        <geometry>
          <box>
            <size>0.096 0.074 0.004</size>
          </box>
        </geometry>
        <surface>
          <contact>
            <ode>
              <min_depth>0.001</min_depth>
              <max_vel>0</max_vel>
            </ode>
          </contact>
          <friction>
            <ode/>
          </friction>
        </surface>
      </collision>
      <collision name="uav_base_link_collision_body_mid">
        <pose>0.00123 0.00075 0.04950 0 0 0</pose>
        <geometry>
          <box>
            <size>0.096 0.074 0.004</size>
          </box>
        </geometry>
        <surface>
          <contact>
            <ode>
              <min_depth>0.001</min_depth>
              <max_vel>0</max_vel>
            </ode>
          </contact>
          <friction>
            <ode/>
          </friction>
        </surface>
      </collision>
      <collision name="uav_base_link_collision_body_top">
        <pose>0.00123 0.00075 0.08400 0 0 0</pose>
        <geometry>
          <box>
            <size>0.104 0.100 0.003</size>
          </box>
        </geometry>
        <surface>
          <contact>
            <ode>
              <min_depth>0.001</min_depth>
              <max_vel>0</max_vel>
            </ode>
          </contact>
          <friction>
            <ode/>
          </friction>
        </surface>
      </collision>
      <collision name="uav_base_link_collision_body_core">
        <pose>0.00250 0.00118 0.06250 0 0 0</pose>
        <geometry>
          <box>
            <size>0.050 0.040 0.020</size>
          </box>
        </geometry>
        <surface>
          <contact>
            <ode>
              <min_depth>0.001</min_depth>
              <max_vel>0</max_vel>
            </ode>
          </contact>
          <friction>
            <ode/>
          </friction>
        </surface>
      </collision>
      <collision name="uav_base_link_collision_canopy_top">
        <pose>-0.01384 -0.00052 0.12550 0 0 0</pose>
        <geometry>
          <box>
            <size>0.090 0.110 0.004</size>
          </box>
        </geometry>
        <surface>
          <contact>
            <ode>
              <min_depth>0.001</min_depth>
              <max_vel>0</max_vel>
            </ode>
          </contact>
          <friction>
            <ode/>
          </friction>
        </surface>
      </collision>
      <collision name="uav_base_link_collision_canopy_left">
        <pose>-0.01384 0.05248 0.10300 0 0 0</pose>
        <geometry>
          <box>
            <size>0.090 0.004 0.041</size>
          </box>
        </geometry>
        <surface>
          <contact>
            <ode>
              <min_depth>0.001</min_depth>
              <max_vel>0</max_vel>
            </ode>
          </contact>
          <friction>
            <ode/>
          </friction>
        </surface>
      </collision>
      <collision name="uav_base_link_collision_canopy_right">
        <pose>-0.01384 -0.05352 0.10300 0 0 0</pose>
        <geometry>
          <box>
            <size>0.090 0.004 0.041</size>
          </box>
        </geometry>
        <surface>
          <contact>
            <ode>
              <min_depth>0.001</min_depth>
              <max_vel>0</max_vel>
            </ode>
          </contact>
          <friction>
            <ode/>
          </friction>
        </surface>
      </collision>
      <collision name="uav_base_link_collision_canopy_front">
        <pose>0.02916 -0.00052 0.10300 0 0 0</pose>
        <geometry>
          <box>
            <size>0.004 0.102 0.041</size>
          </box>
        </geometry>
        <surface>
          <contact>
            <ode>
              <min_depth>0.001</min_depth>
              <max_vel>0</max_vel>
            </ode>
          </contact>
          <friction>
            <ode/>
          </friction>
        </surface>
      </collision>
      <collision name="uav_base_link_collision_canopy_rear">
        <pose>-0.05684 -0.00052 0.10300 0 0 0</pose>
        <geometry>
          <box>
            <size>0.004 0.102 0.041</size>
          </box>
        </geometry>
        <surface>
          <contact>
            <ode>
              <min_depth>0.001</min_depth>
              <max_vel>0</max_vel>
            </ode>
          </contact>
          <friction>
            <ode/>
          </friction>
        </surface>
      </collision>
      <collision name="uav_base_link_collision_body_front_bridge">
        <pose>0.04702 0.00075 0.09332 0 0 -1.571</pose>
        <geometry>
          <box>
            <size>0.094 0.038 0.014</size>
          </box>
        </geometry>
        <surface>
          <contact>
            <ode>
              <min_depth>0.001</min_depth>
              <max_vel>0</max_vel>
            </ode>
          </contact>
          <friction>
            <ode/>
          </friction>
        </surface>
      </collision>
      <collision name="uav_base_link_collision_arm_front_left">
        <pose>0.06297 0.06099 0.02936 0 0.058 0.785</pose>
        <geometry>
          <box>
            <size>0.098 0.030 0.022</size>
          </box>
        </geometry>
        <surface>
          <contact>
            <ode>
              <min_depth>0.001</min_depth>
              <max_vel>0</max_vel>
            </ode>
          </contact>
          <friction>
            <ode/>
          </friction>
        </surface>
      </collision>
      <collision name="uav_base_link_collision_arm_rear_left">
        <pose>-0.06043 0.06102 0.02936 0 0.058 2.356</pose>
        <geometry>
          <box>
            <size>0.098 0.030 0.022</size>
          </box>
        </geometry>
        <surface>
          <contact>
            <ode>
              <min_depth>0.001</min_depth>
              <max_vel>0</max_vel>
            </ode>
          </contact>
          <friction>
            <ode/>
          </friction>
        </surface>
      </collision>
      <collision name="uav_base_link_collision_arm_rear_right">
        <pose>-0.06047 -0.05895 0.02936 0 0.058 -2.356</pose>
        <geometry>
          <box>
            <size>0.098 0.030 0.022</size>
          </box>
        </geometry>
        <surface>
          <contact>
            <ode>
              <min_depth>0.001</min_depth>
              <max_vel>0</max_vel>
            </ode>
          </contact>
          <friction>
            <ode/>
          </friction>
        </surface>
      </collision>
      <collision name="uav_base_link_collision_arm_front_right">
        <pose>0.06174 -0.06122 0.02936 0 0.058 -0.785</pose>
        <geometry>
          <box>
            <size>0.098 0.030 0.022</size>
          </box>
        </geometry>
        <surface>
          <contact>
            <ode>
              <min_depth>0.001</min_depth>
              <max_vel>0</max_vel>
            </ode>
          </contact>
          <friction>
            <ode/>
          </friction>
        </surface>
      </collision>
      <collision name="uav_base_link_collision_leg_front_left_upper">
        <pose>0.04159 0.04045 -0.00324 0 0.906 0.785</pose>
        <geometry>
          <box>
            <size>0.080 0.053 0.030</size>
          </box>
        </geometry>
        <surface>
          <contact>
            <ode>
              <min_depth>0.001</min_depth>
              <max_vel>0</max_vel>
            </ode>
          </contact>
          <friction>
            <ode/>
          </friction>
        </surface>
      </collision>
      <collision name="uav_base_link_collision_leg_front_left_mid">
        <pose>0.08659 0.08545 -0.06441 0 0.906 0.785</pose>
        <geometry>
          <box>
            <size>0.095 0.029 0.010</size>
          </box>
        </geometry>
        <surface>
          <contact>
            <ode>
              <min_depth>0.001</min_depth>
              <max_vel>0</max_vel>
            </ode>
          </contact>
          <friction>
            <ode/>
          </friction>
        </surface>
      </collision>
      <collision name="uav_base_link_collision_leg_front_left_foot">
        <pose>0.10177 0.10063 -0.11708 0 0.906 0.785</pose>
        <geometry>
          <box>
            <size>0.032 0.026 0.010</size>
          </box>
        </geometry>
        <surface>
          <contact>
            <ode>
              <min_depth>0.001</min_depth>
              <max_vel>0</max_vel>
            </ode>
          </contact>
          <friction>
            <ode/>
          </friction>
        </surface>
      </collision>
      <collision name="uav_base_link_collision_leg_front_right_upper">
        <pose>0.04101 -0.04131 -0.00324 0 0.906 -0.785</pose>
        <geometry>
          <box>
            <size>0.080 0.053 0.030</size>
          </box>
        </geometry>
        <surface>
          <contact>
            <ode>
              <min_depth>0.001</min_depth>
              <max_vel>0</max_vel>
            </ode>
          </contact>
          <friction>
            <ode/>
          </friction>
        </surface>
      </collision>
      <collision name="uav_base_link_collision_leg_front_right_mid">
        <pose>0.08601 -0.08631 -0.06441 0 0.906 -0.785</pose>
        <geometry>
          <box>
            <size>0.095 0.029 0.010</size>
          </box>
        </geometry>
        <surface>
          <contact>
            <ode>
              <min_depth>0.001</min_depth>
              <max_vel>0</max_vel>
            </ode>
          </contact>
          <friction>
            <ode/>
          </friction>
        </surface>
      </collision>
      <collision name="uav_base_link_collision_leg_front_right_foot">
        <pose>0.10119 -0.10149 -0.11708 0 0.906 -0.785</pose>
        <geometry>
          <box>
            <size>0.032 0.026 0.010</size>
          </box>
        </geometry>
        <surface>
          <contact>
            <ode>
              <min_depth>0.001</min_depth>
              <max_vel>0</max_vel>
            </ode>
          </contact>
          <friction>
            <ode/>
          </friction>
        </surface>
      </collision>
      <collision name="uav_base_link_collision_leg_rear_right_upper">
        <pose>-0.04159 -0.04138 -0.00324 0 0.906 -2.356</pose>
        <geometry>
          <box>
            <size>0.080 0.053 0.030</size>
          </box>
        </geometry>
        <surface>
          <contact>
            <ode>
              <min_depth>0.001</min_depth>
              <max_vel>0</max_vel>
            </ode>
          </contact>
          <friction>
            <ode/>
          </friction>
        </surface>
      </collision>
      <collision name="uav_base_link_collision_leg_rear_right_mid">
        <pose>-0.08659 -0.08638 -0.06441 0 0.906 -2.356</pose>
        <geometry>
          <box>
            <size>0.095 0.029 0.010</size>
          </box>
        </geometry>
        <surface>
          <contact>
            <ode>
              <min_depth>0.001</min_depth>
              <max_vel>0</max_vel>
            </ode>
          </contact>
          <friction>
            <ode/>
          </friction>
        </surface>
      </collision>
      <collision name="uav_base_link_collision_leg_rear_right_foot">
        <pose>-0.10177 -0.10156 -0.11708 0 0.906 -2.356</pose>
        <geometry>
          <box>
            <size>0.032 0.026 0.010</size>
          </box>
        </geometry>
        <surface>
          <contact>
            <ode>
              <min_depth>0.001</min_depth>
              <max_vel>0</max_vel>
            </ode>
          </contact>
          <friction>
            <ode/>
          </friction>
        </surface>
      </collision>
      <collision name="uav_base_link_collision_leg_rear_left_upper">
        <pose>-0.04010 0.04138 -0.00324 0 0.906 2.356</pose>
        <geometry>
          <box>
            <size>0.080 0.053 0.030</size>
          </box>
        </geometry>
        <surface>
          <contact>
            <ode>
              <min_depth>0.001</min_depth>
              <max_vel>0</max_vel>
            </ode>
          </contact>
          <friction>
            <ode/>
          </friction>
        </surface>
      </collision>
      <collision name="uav_base_link_collision_leg_rear_left_mid">
        <pose>-0.08511 0.08638 -0.06441 0 0.906 2.356</pose>
        <geometry>
          <box>
            <size>0.095 0.029 0.010</size>
          </box>
        </geometry>
        <surface>
          <contact>
            <ode>
              <min_depth>0.001</min_depth>
              <max_vel>0</max_vel>
            </ode>
          </contact>
          <friction>
            <ode/>
          </friction>
        </surface>
      </collision>
      <collision name="uav_base_link_collision_leg_rear_left_foot">
        <pose>-0.10028 0.10156 -0.11708 0 0.906 2.356</pose>
        <geometry>
          <box>
            <size>0.032 0.026 0.010</size>
          </box>
        </geometry>
        <surface>
          <contact>
            <ode>
              <min_depth>0.001</min_depth>
              <max_vel>0</max_vel>
            </ode>
          </contact>
          <friction>
            <ode/>
          </friction>
        </surface>
      </collision>
      <sensor name="uav_air_pressure_sensor" type="air_pressure">
        <always_on>1</always_on>
        <update_rate>50</update_rate>
        <air_pressure>
          <pressure>
            <noise type="gaussian">
              <mean>0</mean>
              <stddev>0.01</stddev>
            </noise>
          </pressure>
        </air_pressure>
      </sensor>
      <sensor name="uav_imu_sensor" type="imu">
        <always_on>1</always_on>
        <update_rate>250</update_rate>
        <imu>
          <angular_velocity>
            <x>
              <noise type="gaussian">
                <mean>0</mean>
                <stddev>0.00018665</stddev>
                <dynamic_bias_stddev>3.8785e-05</dynamic_bias_stddev>
                <dynamic_bias_correlation_time>1000</dynamic_bias_correlation_time>
              </noise>
            </x>
            <y>
              <noise type="gaussian">
                <mean>0</mean>
                <stddev>0.00018665</stddev>
                <dynamic_bias_stddev>3.8785e-05</dynamic_bias_stddev>
                <dynamic_bias_correlation_time>1000</dynamic_bias_correlation_time>
              </noise>
            </y>
            <z>
              <noise type="gaussian">
                <mean>0</mean>
                <stddev>0.00018665</stddev>
                <dynamic_bias_stddev>3.8785e-05</dynamic_bias_stddev>
                <dynamic_bias_correlation_time>1000</dynamic_bias_correlation_time>
              </noise>
            </z>
          </angular_velocity>
          <linear_acceleration>
            <x>
              <noise type="gaussian">
                <mean>0</mean>
                <stddev>0.00186</stddev>
                <dynamic_bias_stddev>0.006</dynamic_bias_stddev>
                <dynamic_bias_correlation_time>300</dynamic_bias_correlation_time>
              </noise>
            </x>
            <y>
              <noise type="gaussian">
                <mean>0</mean>
                <stddev>0.00186</stddev>
                <dynamic_bias_stddev>0.006</dynamic_bias_stddev>
                <dynamic_bias_correlation_time>300</dynamic_bias_correlation_time>
              </noise>
            </y>
            <z>
              <noise type="gaussian">
                <mean>0</mean>
                <stddev>0.00186</stddev>
                <dynamic_bias_stddev>0.006</dynamic_bias_stddev>
                <dynamic_bias_correlation_time>300</dynamic_bias_correlation_time>
              </noise>
            </z>
          </linear_acceleration>
        </imu>
      </sensor>
      <sensor name="uav_navsat_sensor" type="navsat">
        <always_on>1</always_on>
        <update_rate>30</update_rate>
      </sensor>
      <visual name="optical_flow_module_visual">
        <pose>0.005 0.05 0.0123 0 0 0</pose>
        <geometry>
          <box>
            <size>0.030 0.015 0.005</size>
          </box>
        </geometry>
        <material>
          <ambient>0.04 0.04 0.04 1</ambient>
          <diffuse>0.08 0.08 0.08 1</diffuse>
          <specular>0.15 0.15 0.15 1</specular>
        </material>
      </visual>
      <visual name="optical_flow_module_lens_window">
        <pose>0.012 0.05 0.0095 0 0 0</pose>
        <geometry>
          <box>
            <size>0.008 0.008 0.0008</size>
          </box>
        </geometry>
        <material>
          <ambient>0.02 0.03 0.05 1</ambient>
          <diffuse>0.04 0.06 0.08 1</diffuse>
          <specular>0.25 0.25 0.25 1</specular>
        </material>
      </visual>
      <visual name="optical_flow_module_range_window">
        <pose>-0.008 0.05 0.0095 0 0 0</pose>
        <geometry>
          <cylinder>
            <radius>0.0025</radius>
            <length>0.0008</length>
          </cylinder>
        </geometry>
        <material>
          <ambient>0.08 0.08 0.08 1</ambient>
          <diffuse>0.12 0.12 0.12 1</diffuse>
          <specular>0.20 0.20 0.20 1</specular>
        </material>
      </visual>
      <sensor name="uav_optical_flow_camera" type="camera">
        <always_on>1</always_on>
        <update_rate>30</update_rate>
        <pose>0.005 0.05 0.0098 0 1.570796327 0</pose>
        <camera>
          <horizontal_fov>0.25</horizontal_fov>
          <image>
            <width>64</width>
            <height>64</height>
            <format>R8G8B8</format>
          </image>
          <clip>
            <near>0.03</near>
            <far>20.0</far>
          </clip>
        </camera>
        <visualize>false</visualize>
      </sensor>
      <sensor name="uav_optical_flow_range" type="gpu_lidar">
        <always_on>1</always_on>
        <update_rate>30</update_rate>
        <pose>0.005 0.05 0.0098 0 -1.570796327 0</pose>
        <lidar>
          <scan>
            <horizontal>
              <samples>1</samples>
              <resolution>1</resolution>
              <min_angle>0.0</min_angle>
              <max_angle>0.0</max_angle>
            </horizontal>
            <vertical>
              <samples>1</samples>
              <resolution>1</resolution>
              <min_angle>0.0</min_angle>
              <max_angle>0.0</max_angle>
            </vertical>
          </scan>
          <range>
            <min>0.08</min>
            <max>8.0</max>
            <resolution>0.01</resolution>
          </range>
        </lidar>
        <visualize>false</visualize>
      </sensor>
      <visual name="uav_mono_camera_visual">
        <pose>0.0903 0 0.0098 0 1.570796327 0</pose>
        <geometry>
          <box>
            <size>0.008 0.018 0.014</size>
          </box>
        </geometry>
        <material>
          <ambient>0.05 0.05 0.05 1</ambient>
          <diffuse>0.08 0.08 0.08 1</diffuse>
          <specular>0.2 0.2 0.2 1</specular>
        </material>
      </visual>
      <sensor name="uav_mono_camera" type="camera">
        <always_on>1</always_on>
        <update_rate>60</update_rate>
        <pose>0.0903 0 0.0098 0 1.570796327 0</pose>
        <camera>
          <horizontal_fov>1.3962634</horizontal_fov>
          <image>
            <width>1280</width>
            <height>720</height>
            <format>L8</format>
          </image>
          <clip>
            <near>0.05</near>
            <far>100</far>
          </clip>
        </camera>
        <visualize>false</visualize>
      </sensor>
      <visual name="uav_stereo_depth_camera_visual">
        <pose>0.0452 0 0.0918 0 0 0</pose>
        <geometry>
          <mesh>
            <scale>1 1 1</scale>
            <uri>model://uav_base/meshes/camera_orbbec_gemini336_link.stl</uri>
          </mesh>
        </geometry>
        <material>
          <ambient>0.05 0.05 0.05 1</ambient>
          <diffuse>0.08 0.08 0.08 1</diffuse>
          <specular>0.2 0.2 0.2 1</specular>
        </material>
      </visual>
      <sensor name="uav_stereo_depth_camera_rgb" type="camera">
        <always_on>1</always_on>
        <update_rate>30</update_rate>
        <pose>0.0503 0 0.1043 0 0 0</pose>
        <camera>
          <horizontal_fov>1.500983157</horizontal_fov>
          <image>
            <width>1920</width>
            <height>1080</height>
            <format>R8G8B8</format>
          </image>
          <clip>
            <near>0.10</near>
            <far>20.0</far>
          </clip>
        </camera>
        <visualize>false</visualize>
      </sensor>
      <sensor name="uav_stereo_depth_camera_depth" type="depth_camera">
        <always_on>1</always_on>
        <update_rate>30</update_rate>
        <pose>0.0503 0 0.1043 0 0 0</pose>
        <camera>
          <horizontal_fov>1.570796327</horizontal_fov>
          <image>
            <width>1280</width>
            <height>800</height>
            <format>R_FLOAT32</format>
          </image>
          <clip>
            <near>0.10</near>
            <far>20.0</far>
          </clip>
        </camera>
        <visualize>false</visualize>
      </sensor>
    </link>
    <!-- Rotor links keep the configured ordering after FRD->FLU conversion.
         A -Z spin axis in FRD maps to a +Z spin axis in Gazebo FLU. -->
    <link name="uav_rotor_0">
      <gravity>true</gravity>
      <self_collide>false</self_collide>
      <velocity_decay/>
      <pose>0.09 -0.09 0.033 0 0 0</pose>
      <inertial>
          <mass>0.002009615385</mass>
          <inertia>
            <ixx>0.00000001202</ixx>
            <iyy>0.00000081612</iyy>
            <izz>0.000000828081</izz>
          </inertia>
        </inertial>
      <visual name="uav_rotor_0_visual">
        <pose>0 0 0.01 0 0 0</pose>
        <geometry>
          <mesh>
            <scale>0.001 0.001 0.001</scale>
            <uri>model://uav_base/meshes/propeller_5x3.stl</uri>
          </mesh>
        </geometry>
        <material>
          <script>
            <name>Gazebo/DarkGrey</name>
            <uri>file://media/materials/scripts/gazebo.material</uri>
          </script>
        </material>
      </visual>
      <visual name="uav_rotor_0_visual_motor_bell">
        <pose>0 0 0 0 0 0</pose>
        <geometry>
          <mesh>
            <scale>0.5 0.5 0.5</scale>
            <uri>model://uav_base/meshes/motor_2306_bell.dae</uri>
          </mesh>
        </geometry>
      </visual>
      <collision name="uav_rotor_0_collision">
        <pose>0 0 0.01 0 0 0</pose>
        <geometry>
          <box>
            <size>0.139615384615 0.008461538462 0.000423076923</size>
          </box>
        </geometry>
        <surface>
          <contact>
            <ode>
              <min_depth>0.001</min_depth>
              <max_vel>0</max_vel>
            </ode>
          </contact>
          <friction>
            <ode/>
          </friction>
        </surface>
      </collision>
    </link>
    <joint name="uav_rotor_0_joint" type="revolute">
      <parent>uav_base_link</parent>
      <child>uav_rotor_0</child>
      <axis>
        <xyz>0 0 1</xyz>
        <limit>
          <lower>-1e+16</lower>
          <upper>1e+16</upper>
        </limit>
        <dynamics>
          <spring_reference>0</spring_reference>
          <spring_stiffness>0</spring_stiffness>
        </dynamics>
      </axis>
    </joint>
    <link name="uav_rotor_1">
      <gravity>true</gravity>
      <self_collide>false</self_collide>
      <velocity_decay/>
      <pose>-0.09 0.09 0.033 0 0 0</pose>
      <inertial>
          <mass>0.002009615385</mass>
          <inertia>
            <ixx>0.00000001202</ixx>
            <iyy>0.00000081612</iyy>
            <izz>0.000000828081</izz>
          </inertia>
        </inertial>
      <visual name="uav_rotor_1_visual">
        <pose>0 0 0.01 0 0 0</pose>
        <geometry>
          <mesh>
            <scale>0.001 0.001 0.001</scale>
            <uri>model://uav_base/meshes/propeller_5x3.stl</uri>
          </mesh>
        </geometry>
        <material>
          <script>
            <name>Gazebo/DarkGrey</name>
            <uri>file://media/materials/scripts/gazebo.material</uri>
          </script>
        </material>
      </visual>
      <visual name="uav_rotor_1_visual_motor_bell">
        <pose>0 0 0 0 0 0</pose>
        <geometry>
          <mesh>
            <scale>0.5 0.5 0.5</scale>
            <uri>model://uav_base/meshes/motor_2306_bell.dae</uri>
          </mesh>
        </geometry>
      </visual>
      <collision name="uav_rotor_1_collision">
        <pose>0 0 0.01 0 0 0</pose>
        <geometry>
          <box>
            <size>0.139615384615 0.008461538462 0.000423076923</size>
          </box>
        </geometry>
        <surface>
          <contact>
            <ode>
              <min_depth>0.001</min_depth>
              <max_vel>0</max_vel>
            </ode>
          </contact>
          <friction>
            <ode/>
          </friction>
        </surface>
      </collision>
    </link>
    <joint name="uav_rotor_1_joint" type="revolute">
      <parent>uav_base_link</parent>
      <child>uav_rotor_1</child>
      <axis>
        <xyz>0 0 1</xyz>
        <limit>
          <lower>-1e+16</lower>
          <upper>1e+16</upper>
        </limit>
        <dynamics>
          <spring_reference>0</spring_reference>
          <spring_stiffness>0</spring_stiffness>
        </dynamics>
      </axis>
    </joint>
    <link name="uav_rotor_2">
      <gravity>true</gravity>
      <self_collide>false</self_collide>
      <velocity_decay/>
      <pose>0.09 0.09 0.033 0 0 0</pose>
      <inertial>
          <mass>0.002009615385</mass>
          <inertia>
            <ixx>0.00000001202</ixx>
            <iyy>0.00000081612</iyy>
            <izz>0.000000828081</izz>
          </inertia>
        </inertial>
      <visual name="uav_rotor_2_visual">
        <pose>0 0 0.01 0 0 0</pose>
        <geometry>
          <mesh>
            <scale>0.001 0.001 0.001</scale>
            <uri>model://uav_base/meshes/propeller_5x3.stl</uri>
          </mesh>
        </geometry>
        <material>
          <script>
            <name>Gazebo/DarkGrey</name>
            <uri>file://media/materials/scripts/gazebo.material</uri>
          </script>
        </material>
      </visual>
      <visual name="uav_rotor_2_visual_motor_bell">
        <pose>0 0 0 0 0 0</pose>
        <geometry>
          <mesh>
            <scale>0.5 0.5 0.5</scale>
            <uri>model://uav_base/meshes/motor_2306_bell.dae</uri>
          </mesh>
        </geometry>
      </visual>
      <collision name="uav_rotor_2_collision">
        <pose>0 0 0.01 0 0 0</pose>
        <geometry>
          <box>
            <size>0.139615384615 0.008461538462 0.000423076923</size>
          </box>
        </geometry>
        <surface>
          <contact>
            <ode>
              <min_depth>0.001</min_depth>
              <max_vel>0</max_vel>
            </ode>
          </contact>
          <friction>
            <ode/>
          </friction>
        </surface>
      </collision>
    </link>
    <joint name="uav_rotor_2_joint" type="revolute">
      <parent>uav_base_link</parent>
      <child>uav_rotor_2</child>
      <axis>
        <xyz>0 0 1</xyz>
        <limit>
          <lower>-1e+16</lower>
          <upper>1e+16</upper>
        </limit>
        <dynamics>
          <spring_reference>0</spring_reference>
          <spring_stiffness>0</spring_stiffness>
        </dynamics>
      </axis>
    </joint>
    <link name="uav_rotor_3">
      <gravity>true</gravity>
      <self_collide>false</self_collide>
      <velocity_decay/>
      <pose>-0.09 -0.09 0.033 0 0 0</pose>
      <inertial>
          <mass>0.002009615385</mass>
          <inertia>
            <ixx>0.00000001202</ixx>
            <iyy>0.00000081612</iyy>
            <izz>0.000000828081</izz>
          </inertia>
        </inertial>
      <visual name="uav_rotor_3_visual">
        <pose>0 0 0.01 0 0 0</pose>
        <geometry>
          <mesh>
            <scale>0.001 0.001 0.001</scale>
            <uri>model://uav_base/meshes/propeller_5x3.stl</uri>
          </mesh>
        </geometry>
        <material>
          <script>
            <name>Gazebo/DarkGrey</name>
            <uri>file://media/materials/scripts/gazebo.material</uri>
          </script>
        </material>
      </visual>
      <visual name="uav_rotor_3_visual_motor_bell">
        <pose>0 0 0 0 0 0</pose>
        <geometry>
          <mesh>
            <scale>0.5 0.5 0.5</scale>
            <uri>model://uav_base/meshes/motor_2306_bell.dae</uri>
          </mesh>
        </geometry>
      </visual>
      <collision name="uav_rotor_3_collision">
        <pose>0 0 0.01 0 0 0</pose>
        <geometry>
          <box>
            <size>0.139615384615 0.008461538462 0.000423076923</size>
          </box>
        </geometry>
        <surface>
          <contact>
            <ode>
              <min_depth>0.001</min_depth>
              <max_vel>0</max_vel>
            </ode>
          </contact>
          <friction>
            <ode/>
          </friction>
        </surface>
      </collision>
    </link>
    <joint name="uav_rotor_3_joint" type="revolute">
      <parent>uav_base_link</parent>
      <child>uav_rotor_3</child>
      <axis>
        <xyz>0 0 1</xyz>
        <limit>
          <lower>-1e+16</lower>
          <upper>1e+16</upper>
        </limit>
        <dynamics>
          <spring_reference>0</spring_reference>
          <spring_stiffness>0</spring_stiffness>
        </dynamics>
      </axis>
    </joint>
  </model>
</sdf>
